Workbook

Sheet Dashboard
A1: DSA TRAINING DASHBOARD - NVIDIA & AI-INFRASTRUCTURE SYSTEMS
A2: Started: 01 Oct 2026 | Ends: 17 Mar 2027 | Target: NVIDIA, Hyperscalers & AI-Infra Systems | Fill ProblemDB & DayPlan honestly
A3: TODAY'S WORKFLOW | D3: Failure Category | E3: Count | G3: QUICK-START DAILY PROTOCOL
A4: Current day | B4: =MIN(168,COUNTIF(DayPlan!$W$2:$W$169,"Yes")+1) | D4: F1-Understand | E4: =COUNTIF(FailureLog!$D$2:$D$500,D4)+COUNTIF(ProblemDB!$M$2:$M$750,D4) | G4: 1. Open DayPlan -> go to 'Current day' row. Do exactly that row.
A5: Current week | B5: =ROUNDUP($B4/7,0) | D5: F2-Pattern | E5: =COUNTIF(FailureLog!$D$2:$D$500,D5)+COUNTIF(ProblemDB!$M$2:$M$750,D5) | G5: 2. Write target TC from constraints BEFORE touching the keyboard.
A6: TODAY: objective | B6: =IFERROR(INDEX(DayPlan!$D$2:$D$169,$B4),"") | D6: F3-Derive | E6: =COUNTIF(FailureLog!$D$2:$D$500,D6)+COUNTIF(ProblemDB!$M$2:$M$750,D6) | G6: 3. Obey the Stuck Protocol (see README): 0 -> 10 -> 20 -> 30 min checkpoints.
A7: TODAY: pattern | B7: =IFERROR(INDEX(DayPlan!$E$2:$E$169,$B4),"") | D7: F4-WrongDS | E7: =COUNTIF(FailureLog!$D$2:$D$500,D7)+COUNTIF(ProblemDB!$M$2:$M$750,D7) | G7: 4. Log every problem in ProblemDB the same day. Review dates auto-compute.
A8: TODAY: mode / help | B8: =IFERROR(INDEX(DayPlan!$J$2:$J$169,$B4)&" | "&INDEX(DayPlan!$K$2:$K$169,$B4),"") | D8: F5-Complexity | E8: =COUNTIF(FailureLog!$D$2:$D$500,D8)+COUNTIF(ProblemDB!$M$2:$M$750,D8) | G8: 5. Log every failure in FailureLog with a category + one preventive rule.
A9: TODAY: problems | B9: =IFERROR(INDEX(DayPlan!$L$2:$L$169,$B4)&" | "&INDEX(DayPlan!$O$2:$O$169,$B4),"") | D9: F6-Implementation | E9: =COUNTIF(FailureLog!$D$2:$D$500,D9)+COUNTIF(ProblemDB!$M$2:$M$750,D9) | G9: 6. Sunday: fill WeeklyAssessment. Let the data steer the next week.
A10: TODAY: tutorial? | B10: =IFERROR(IF(INDEX(DayPlan!$G$2:$G$169,$B4)="YES",INDEX(DayPlan!$H$2:$H$169,$B4)&" ("&INDEX(DayPlan!$I$2:$I$169,$B4)&" min)","NO tutorial - struggle first"),"") | D10: F7-EdgeCase | E10: =COUNTIF(FailureLog!$D$2:$D$500,D10)+COUNTIF(ProblemDB!$M$2:$M$750,D10) | G10: 7. Diagnostics on Days 28/56/84/98. Unlabelled. Timed. No hints. Real measurements.
A11: Days completed | B11: =COUNTIF(DayPlan!$W$2:$W$169,"Yes") | D11: F8-Debugging | E11: =COUNTIF(FailureLog!$D$2:$D$500,D11)+COUNTIF(ProblemDB!$M$2:$M$750,D11) | G11: 8. Master YouTube Directory: Check 'YouTubeChannels' sheet for flagship playlists.
A12: Program progress | B12: =IFERROR($B11/168,0) | D12: F9-Forgot | E12: =COUNTIF(FailureLog!$D$2:$D$500,D12)+COUNTIF(ProblemDB!$M$2:$M$750,D12)
A13: SOLVE QUALITY METRICS | D13: F10-Pressure | E13: =COUNTIF(FailureLog!$D$2:$D$500,D13)+COUNTIF(ProblemDB!$M$2:$M$750,D13) | G13: SIGNS THE PLAN IS WORKING
A14: Problems attempted | B14: =COUNTA(ProblemDB!$A$2:$A$750) | D14: F11-HintDependent | E14: =COUNTIF(FailureLog!$D$2:$D$500,D14)+COUNTIF(ProblemDB!$M$2:$M$750,D14) | G14: [OK] Time-to-pattern dropping at each diagnostic
A15: Solved independently | B15: =COUNTIF(ProblemDB!$G$2:$G$750,"Yes") | D15: F12-CantExplain | E15: =COUNTIF(FailureLog!$D$2:$D$500,D15)+COUNTIF(ProblemDB!$M$2:$M$750,D15) | G15: [OK] Hint-dependency rate below 25% by week 8
A16: Solved with hints | B16: =COUNTIFS(ProblemDB!$I$2:$I$750,">0",ProblemDB!$J$2:$J$750,"<>Yes") | G16: [OK] Can reconstruct any pattern without notes 3 days later
A17: Needed the solution | B17: =COUNTIF(ProblemDB!$J$2:$J$750,"Yes") | D17: MASTER YOUTUBE DIRECTORY | G17: [OK] Mock scores increasing
A18: Independent-solve rate | B18: =IFERROR($B15/$B14,0) | D18: =HYPERLINK("#'YouTubeChannels'!A1", "📺 Open Master YouTube Directory (10 Creators) ↗")
A19: Hint-dependency rate | B19: =IFERROR(($B16+$B17)/$B14,0) | D19: Striver • Aditya Verma • Pratyush • Babbar • NeetCode | G19: SIGNS YOU NEED TO ADJUST
A20: Problems mastered | B20: =COUNTIF(ProblemDB!$S$2:$S$750,"Yes") | G20: [NO] Same failure category 3+ weeks in a row
A21: Avg solve time (min) | B21: =IFERROR(ROUND(AVERAGE(ProblemDB!$H$2:$H$750),0),0) | G21: [NO] Hint-dependency above 40% for 2+ weeks
A22: 2nd solutions found | B22: =COUNTIF(ProblemDB!$X$2:$X$750,"Yes") | G22: [NO] Time-to-pattern not dropping between diagnostics
A23: INTERVIEW READINESS | G23: [NO] Can solve only when problem is labelled with the pattern
A24: Mock/diagnostic avg (/10) | B24: =IFERROR(ROUND(AVERAGE(MockInterviews!$N$2:$N$30),1),0) | G24: [NO] Cannot reconstruct a solution 2 days after solving it
A25: Avg time-to-pattern (min) | B25: =IFERROR(ROUND(AVERAGE(MockInterviews!$J$2:$J$30),1),0)
A26: Avg pattern mastery (/5) | B26: =IFERROR(ROUND(AVERAGE(PatternLibrary!$J$2:$J$43),2),0)
A27: Reviews due today | B27: =COUNTIFS(ProblemDB!$P$2:$P$750,"<="&TODAY(),ProblemDB!$S$2:$S$750,"<>Yes")
A28: INTERVIEW READINESS SCORE | B28: =IF($B14<5,0,ROUND(30*MIN(1,MAX(0,IFERROR($B18/0.80,0)))+25*MIN(1,MAX(0,IFERROR((1-$B19)/0.80,0)))+25*MIN(1,MAX(0,IFERROR($B24/10,0)))+20*IF($B25=0,0,MIN(1,MAX(0,IFERROR((12-$B25)/8,0)))),0))
A29: PATTERN MASTERY & HEALTH
A30: Strongest pattern (self-rated) | B30: =IFERROR(INDEX(PatternLibrary!$A$2:$A$43,MATCH(MAX(PatternLibrary!$J$2:$J$43),PatternLibrary!$J$2:$J$43,0)),"Rate patterns first")
A31: Weakest pattern (self-rated) | B31: =IFERROR(INDEX(PatternLibrary!$A$2:$A$43,MATCH(MINIFS(PatternLibrary!$J$2:$J$43,PatternLibrary!$J$2:$J$43,">0"),PatternLibrary!$J$2:$J$43,0)),"Rate patterns first")
A32: Most failure-prone category | B32: =IF(MAX($E$4:$E$15)=0,"No failures logged yet",INDEX($D$4:$D$15,MATCH(MAX($E$4:$E$15),$E$4:$E$15,0))&" ("&MAX($E$4:$E$15)&" failures)")
A33: Current level | B33: =IF($B14<10,"Unmeasured - solve 10+ logged problems first",IF($B28<35,"Beginner: knows topics but pattern-blind",IF($B28<55,"Intermediate: recognises common patterns",IF($B28<75,"Strong: derives most solutions independently","Expert-level: can derive unfamiliar problems under pressure"))))
A34: SYSTEM OPERATING GUIDE

Sheet README
A1: DSA TRAINING SYSTEM - AI INFRASTRUCTURE (168 DAYS / 24 WEEKS)
A2: The real metric: how fast you turn an unfamiliar problem into a correct, efficient algorithm. Not how many problems you have solved.
A4: THE ONLY METRIC THAT MATTERS
A5: Problem count is a lagging metric and a vanity number. The metric that predicts interview success: * Time-to-pattern on UNLABELLED problems (target: <5 min for Medium by week 10) * Independent-solve rate (target: >70% by week 12) * Hint-dependency rate (target: <20% by week 10) * Ability to reconstruct any solved problem from memory 3 days later Dashboard tracks all four. Fill it honestly or it becomes useless.
A7: DAILY BLOCK STRUCTURE (1-2 hours total)
A8: A) RETRIEVAL [10-15 min] From memory, no notes: state yesterday's pattern trigger + invariant + complexity. If you cannot, add it to ReviewQueue immediately. B) CONCEPT / TUTORIAL [0-25 min - ONLY if DayPlan says YES] Read the DayPlan tutorial column. If it says NO, do not watch anything. The urge to watch a tutorial instead of struggling is a productivity trap. C) DEEP SOLVING [45-70 min - the real training block] Obey the STUCK PROTOCOL below. No shortcuts. D) RECONSTRUCTION [10 min] Close your solution. Open a blank file. Rebuild it from memory. If you cannot reconstruct it, you did not learn it. E) FAILURE ANALYSIS [5 min] Log every failure in FailureLog with an honest category + one preventive rule. F) REVIEW [10 min] Top item from ReviewQueue. Retrieval only - no re-reading.
A10: THE STUCK PROTOCOL (non-negotiable, enforced in DayPlan column)
A11: 0-10 min -> NO help. Restate the problem in your own words. Write constraints. Write brute-force + its TC. Write target TC. Write 2-3 candidate approaches. 10-20 min -> ONE conceptual hint only. No code. No data-structure name if avoidable. Hint = a question that points you toward the right abstraction. 20-30 min -> Stronger hint: name the pattern or the key invariant. Still no implementation. 30+ min -> Read ONLY the core approach (2-3 sentences). Then close it. Implement entirely from scratch - never copy code. If you read code -> problem is auto-logged as "Solution Viewed = Yes" and re-queued at +1 day. If you solve with hints -> re-queued at +3 days, not +7. The goal: "I understand WHY this solution exists." NOT "I understood it after being shown."
A13: PHASE SEQUENCE FOR EVERY IMPORTANT PROBLEM
A14: 1. UNDERSTAND - What is asked? What are constraints? What changes? What is reusable? 2. PREDICT - Write target TC from constraints. List 2-3 approaches. Name the bottleneck. 3. DERIVE - Attempt yourself. Use stuck protocol if needed. 4. IMPLEMENT - Write clean code. 5. ATTACK - Test: empty input, single element, all duplicates, max n, negatives, overflow, adversarial order. 6. OPTIMIZE - Can TC improve? If no, can SC improve? Is there a hidden invariant? 7. RECONSTRUCT - Close everything. Rebuild from memory and explain aloud. 8. SCHEDULE - ProblemDB auto-computes review dates based on your performance.
A16: TUTORIAL RULES (35 curated tutorials across 168 days)
A17: Watch BEFORE a problem only when the mental model is genuinely new (DayPlan marks these explicitly). Do NOT watch because a specific problem is hard. Struggle first. Watch AFTER only when you failed to recognise the SAME pattern twice. Rewatch only if you cannot reconstruct the concept from memory. For every tutorial, extract: * The TRIGGER (what wording in a problem should activate this pattern?) * The INVARIANT (what remains true throughout the algorithm?) * The COMPLEXITY ARGUMENT (why is it O(n)? O(n log n)? - derive it, do not accept it) Do NOT memorise the presenter's code. That is passive consumption, not learning.
... A50: Curated tutorial channels: - Striver (take U forward) - algorithmic patterns & technical interview rigor - Aditya Verma - intuition & recurrence templates (DP, Stack, Sliding Window, BS) - Love Babbar (CodeHelp) - clear structural breakdowns & Hindi explanations - Padho with Pratyush - pattern-based DSA mastery, algorithmic pattern recognition & FAANG problem archetypes - NeetCode (neetcode.io) - concise visual problem walkthroughs & clean code - Specialized channels: Abdul Bari (algorithms), WilliamFiset (graphs), Errichto (range trees), Martin Thompson (lock-free), CMU DB (paging) See the dedicated 'YouTubeChannels' sheet tab in this workbook for direct 1-click links to master playlists and channel URLs.

Sheet DayPlan
A1: Day | B1: Week | C1: Date | D1: Objective | E1: Pattern | F1: Concept | G1: Tutorial? | H1: Tutorial Topic | I1: Tut min | J1: Mode | K1: Help / Stuck Protocol | L1: Problem 1 | M1: P1 Diff | N1: P1 Target min | O1: Problem 2 | P1: P2 Diff | Q1: P2 Target min | R1: Review Problem | S1: Reconstruction Task | T1: Assessment Question | U1: AI-Infra Connection | V1: Skill Gained | W1: Completed? | X1: Actual min | Y1: Notes | Z1: Failure Category | AA1: 2nd-Sol? | AB1: YouTube Tutorial ↗
A2: 1 | B2: 1 | C2: 46296 | D2: Set up C++ environment, learn syntax, types, and get your very first green Accepted checkmark on LeetCode without intimidation | E2: C++ Fundamentals & I/O | F2: Basic syntax, #include <iostream>, int main(), primitive types, cin/cout, LeetCode function signatures | G2: YES | H2: =HYPERLINK("https://www.youtube.com/watch?v=EAR7De6Goz4", "C++ Setup, Syntax & LeetCode Workflow") | I2: 30 | J2: Untimed | K2: Tutorial & step-by-step guidance | L2: LC 2235 Add Two Integers | M2: E | N2: 5 | O2: LC 2469 Convert the Temperature | P2: E | Q2: 10 | R2: - | S2: Write a minimal C++ program with main(), cin/cout, and basic type declarations from memory | T2: Did your code compile without syntax errors and pass all tests on LeetCode? Yes/No | U2: Every GPU kernel in CUDA and AI engine is written in static, strongly-typed C++ | V2: C++ syntax & environment setup | AB2: =HYPERLINK("https://www.youtube.com/watch?v=EAR7De6Goz4", "▶ Watch (Striver) ↗")
A3: 2 | B3: 1 | C3: 46297 | D3: Master if-else logic and loop mechanics (for, while); learn to step-trace variables on paper before typing | E3: Conditionals & Loops | F3: if/else branching; for and while loop bounds; step-tracing variables on paper; digit extraction via % 10 and / 10 | G3: YES | H3: =HYPERLINK("https://www.youtube.com/watch?v=p3YUQB9-B1g", "Loop Mechanics & Tracing on Paper") | I3: 25 | J3: Untimed | K3: Step trace on paper first | L3: LC 9 Palindrome Number | M3: E | N3: 15 | O3: LC 1480 Running Sum of 1d Array | P3: E | Q3: 10 | R3: LC 2235 Add Two Integers | S3: Trace loop states on paper for n = 121 (x % 10, x / 10, rev) without running code | T3: Did you trace the loop iteration by iteration on paper before submitting? | U3: Loop bounds and stepping control thread-grid execution in GPU blocks | V3: Loop execution & state tracing | AB3: =HYPERLINK("https://www.youtube.com/watch?v=p3YUQB9-B1g", "▶ Watch (Gate Smashers) ↗")
A4: 3 | B4: 1 | C4: 46298 | D4: Demystify Big-O through loop iterations: 1 loop = O(N), nested loops = O(N^2), 10^8 operations/sec CPU limit | E4: Complexity calibration | F4: Loop counting: 1 loop = O(N), 2 nested loops = O(N^2), binary halving = O(log N); modern CPUs do ~10^8 ops/sec; why N=10^5 causes TLE on O(N^2) | G4: YES | H4: =HYPERLINK("https://www.youtube.com/watch?v=9TlHvipP5yA", "Time & Space Complexity from Loops") | I4: 30 | J4: Untimed | K4: Count loop operations | L4: LC 1929 Concatenation of Array | M4: E | N4: 10 | O4: LC 2011 Final Value of Variable After Operations | P4: E | Q4: 10 | R4: LC 9 Palindrome Number | S4: Write the 10^8 rule: given N = 20, 500, 5000, 10^5, 10^6, 10^9, state max feasible Big-O | T4: Can you calculate Big-O of a nested loop without guessing? | U4: Latency budgets in NVIDIA GPU kernels depend on input scale, not intuition | V4: Constraint-first thinking | AB4: =HYPERLINK("https://www.youtube.com/watch?v=9TlHvipP5yA", "▶ Watch (Abdul Bari) ↗")
A5: 4 | B5: 1 | C5: 46299 | D5: Understand memory passing: pass-by-value vs pass-by-reference (&), and dynamic arrays (std::vector) | E5: Memory References & Vectors | F5: Pass by value vs reference (&); std::vector<int>, push_back(), size(), indexing; range-based for loops; avoiding copy overhead | G5: YES | H5: =HYPERLINK("https://www.youtube.com/watch?v=WgMPrLX-zsA", "C++ Vectors & Pass-by-Reference (&)") | I5: 25 | J5: Untimed | K5: Understand memory passing | L5: LC 27 Remove Element | M5: E | N5: 15 | O5: LC 26 Remove Duplicates from Sorted Array | P5: E | Q5: 15 | R5: LC 1480 Running Sum of 1d Array | S5: Explain why passing vector<int>& avoids an O(N) memory copy in RAM/cache | T5: Did you use in-place write pointer without creating an auxiliary vector? | U5: Zero-copy pointer passing is mandatory in high-performance GPU tensor engines | V5: In-place array manipulation | AB5: =HYPERLINK("https://www.youtube.com/watch?v=WgMPrLX-zsA", "▶ Watch (CodeHelp - by Babbar) ↗")
A6: 5 | B6: 1 | C6: 46300 | D6: Learn to maintain running state (min, max, count) in a single pass without extra memory | E6: Array Traversal & Running State | F6: Initializing sentinel bounds (INT_MAX, INT_MIN); single-pass running tracking; in-place array shifting | G6: YES | H6: =HYPERLINK("https://www.youtube.com/watch?v=37E9ckMDdTk", "Array Traversal & In-Place Shifts") | I6: 20 | J6: Untimed | K6: Single-pass invariant | L6: LC 283 Move Zeroes | M6: E | N6: 15 | O6: LC 1752 Check if Array Is Sorted and Rotated | P6: E | Q6: 20 | R6: LC 26 Remove Duplicates from Sorted Array | S6: Write Move Zeroes with 2 pointers without using an auxiliary vector from memory | T6: Could you solve Move Zeroes in O(1) auxiliary space? | U6: In-place compaction mirrors zero-copy buffer compaction in network pipelines | V6: Single-pass running state | AB6: =HYPERLINK("https://www.youtube.com/watch?v=37E9ckMDdTk", "▶ Watch (Striver) ↗")
A7: 6 | B7: 1 | C7: 46301 | D7: Discover opposite-end two pointers: moving left and right pointers towards the center with clear termination | E7: Two pointers (opposite ends) | F7: left = 0, right = n - 1; while (left < right); inward convergence; alphanumeric filtering | G7: YES | H7: =HYPERLINK("https://www.youtube.com/watch?v=jJXJ16kPFWg", "Two Pointers: Inward Convergence") | I7: 20 | J7: Untimed | K7: Two pointers opposite ends | L7: LC 125 Valid Palindrome | M7: E | N7: 15 | O7: LC 344 Reverse String | P7: E | Q7: 10 | R7: LC 283 Move Zeroes | S7: Prove why left < right terminates correctly and what happens on odd vs even lengths | T7: Did you handle punctuation and uppercase without extra array allocation? | U7: Bidirectional stream compaction in ring buffers | V7: Inward pointer convergence | AB7: =HYPERLINK("https://www.youtube.com/watch?v=jJXJ16kPFWg", "▶ Watch (NeetCode) ↗")
A8: 7 | B8: 1 | C8: 46302 | D8: Lock in Week 1 patterns: syntax, loop mechanics, vectors, and in-place pointers without looking at solutions | E8: Review/audit | F8: Retention without notes: C++ syntax, loops, vectors, in-place pointer shifts | G8: NO | H8: - | J8: Untimed | K8: Notes forbidden | L8: LC 9 Palindrome Number | M8: E | N8: 15 | O8: LC 283 Move Zeroes | P8: E | Q8: 15 | R8: All Week 1 problems | S8: Re-solve Palindrome Number and Move Zeroes on a blank editor with zero notes | T8: Can you write clean, compiling C++ vector code without syntax errors? | U8: Foundational fluency is required before hardware-aware optimization | V8: Retention + self-audit | AB8: —
A9: 8 | B9: 2 | C9: 46303 | D9: Turn counting into O(1) lookups: frequency arrays count[26] vs unordered_map | E9: Frequency/counting + hashing | F9: Direct index hashing via s[i] - 'a'; hash map as an index; O(1) average lookup vs O(N) linear search | G9: YES | H9: =HYPERLINK("https://www.youtube.com/watch?v=KEs5UyBJ39g", "Hashing & Frequency Counting") | I9: 30 | J9: Untimed | K9: Hash map as index | L9: LC 242 Valid Anagram | M9: E | N9: 15 | O9: LC 217 Contains Duplicate | P9: E | Q9: 12 | R9: LC 125 Valid Palindrome | S9: Explain why int count[26] is 10x faster than unordered_map due to L1 cache locality | T9: Could you design the frequency array yourself without hints? | U9: Direct index tables underpin GPU kernel launch lookup tables | V9: Hash key design | AB9: =HYPERLINK("https://www.youtube.com/watch?v=KEs5UyBJ39g", "▶ Watch (Striver) ↗")
A10: 9 | B10: 2 | C10: 46304 | D10: Master the complement lookup: transforming O(N^2) brute force into O(N) single-pass with a hash map | E10: Complement Lookup (Hash Map) | F10: For each x, check if target - x is in map; value -> index map; single-pass lookup | G10: YES | H10: =HYPERLINK("https://www.youtube.com/watch?v=KLlXCFG5TnA", "Two Sum & Stock Mental Model") | I10: 25 | J10: Untimed | K10: Complement lookup | L10: LC 1 Two Sum | M10: E | N10: 15 | O10: LC 121 Best Time to Buy & Sell Stock | P10: E | Q10: 15 | R10: LC 217 Contains Duplicate | S10: Derive Two Sum brute force O(N^2) vs hash map O(N) on paper; explain one-pass complement check | T10: Did you state why one-pass map prevents using the same element twice? | U10: Key-value indexing in high-throughput inference caches | V10: Complement lookup | AB10: =HYPERLINK("https://www.youtube.com/watch?v=KLlXCFG5TnA", "▶ Watch (NeetCode) ↗")
A11: 10 | B11: 2 | C11: 46305 | D11: Learn when sorting unlocks two pointers: achieving O(N) time and O(1) space without hash map memory overhead | E11: Two pointers (sorted input) | F11: If sorted: sum < target -> left++; sum > target -> right--; eliminating entire search halves | G11: YES | H11: =HYPERLINK("https://www.youtube.com/watch?v=cQ1Oz4ckceM", "Two Pointers on Sorted Arrays") | I11: 20 | J11: Untimed | K11: Sorted two pointers | L11: LC 167 Two Sum II | M11: E | N11: 15 | O11: LC 977 Squares of a Sorted Array | P11: E | Q11: 18 | R11: LC 1 Two Sum | S11: Prove why Two Sum II on sorted input never misses the answer with two pointers | T11: Did you avoid allocating an O(N) hash map when the input is sorted? | U11: Sorted shard scans and merge joins in distributed columnar databases | V11: Monotonic pointer proof | AB11: =HYPERLINK("https://www.youtube.com/watch?v=cQ1Oz4ckceM", "▶ Watch (NeetCode) ↗")
A12: 11 | B12: 2 | C12: 46306 | D12: Learn partial-sum precomputation to answer any range sum query in O(1) time | E12: Prefix/suffix reasoning | F12: prefix[i] = prefix[i-1] + nums[i]; range [L, R] = prefix[R] - prefix[L-1]; avoiding repeated O(N) scans | G12: YES | H12: =HYPERLINK("https://www.youtube.com/watch?v=DhFh8Kw7ymk", "Prefix Sum Fundamentals") | I12: 25 | J12: Untimed | K12: Precompute partial sums | L12: LC 724 Find Pivot Index | M12: E | N12: 15 | O12: LC 303 Range Sum Query - Immutable | P12: E | Q12: 15 | R12: LC 121 Best Time to Buy & Sell Stock | S12: Write the prefix sum formula for range [L, R] and explain the L=0 edge case from memory | T12: Can you state the loop invariant of the prefix sum array in one sentence? | U12: Cumulative metrics and rolling latency telemetry over time-series data | V12: Reuse of partial results | AB12: =HYPERLINK("https://www.youtube.com/watch?v=DhFh8Kw7ymk", "▶ Watch (Striver) ↗")
A13: 12 | B13: 2 | C13: 46307 | D13: Learn to slide a window of size K in O(1) per step by adding incoming and subtracting outgoing | E13: Sliding window (fixed) | F13: Fixed size K: compute initial window of size K; then loop i from K to N-1, updating sum += nums[i] - nums[i-K] | G13: YES | H13: =HYPERLINK("https://www.youtube.com/watch?v=EHCGAZBbB88", "Sliding Window: Fixed Size") | I13: 25 | J13: Untimed | K13: Fixed window slide | L13: LC 643 Maximum Average Subarray I | M13: E | N13: 15 | O13: LC 1876 Substrings of Size Three with Distinct Characters | P13: E | Q13: 15 | R13: LC 724 Find Pivot Index | S13: Write the sliding window sum update step: sum += incoming - outgoing from memory | T13: Did you avoid recomputing the sum of K elements at each step? | U13: Sliding rate-limit windows and token buckets in API gateways | V13: Fixed window sliding | AB13: =HYPERLINK("https://www.youtube.com/watch?v=EHCGAZBbB88", "▶ Watch (Aditya Verma) ↗")
A14: 13 | B14: 2 | C14: 46308 | D14: Understand dynamic window expansion and shrinking based on monotonic conditions | E14: Sliding window (variable) | F14: Expand right pointer; while (condition violated) shrink left pointer; tracking window metrics | G14: YES | H14: =HYPERLINK("https://www.youtube.com/watch?v=cyu_nuW5utA", "Sliding Window: Variable Size") | I14: 25 | J14: Untimed | K14: Expand right, shrink left | L14: LC 209 Minimum Size Subarray Sum | M14: M | N14: 25 | O14: LC 1004 Max Consecutive Ones III | P14: M | Q14: 25 | R14: LC 643 Maximum Average Subarray I | S14: Write the expand and shrink loop conditions for LC 209; explain why total steps is 2*N -> O(N) | T14: Did you understand why the nested while loop still yields O(N) amortized time? | U14: Dynamic queue window sizing under varying network packet congestion | V14: Variable window invariants | AB14: =HYPERLINK("https://www.youtube.com/watch?v=cyu_nuW5utA", "▶ Watch (Aditya Verma) ↗")
A15: 14 | B15: 2 | C15: 46309 | D15: Comprehensive test across all linear foundations: Vectors, Hashing, Two Pointers, Prefix Sum, Sliding Window | E15: Review/audit | F15: Pattern discrimination: recognizing whether a problem requires Hashing, Two Pointers, or Sliding Window | G15: NO | H15: - | J15: Timed-40 | K15: No hints | L15: LC 1 Two Sum | M15: E | N15: 12 | O15: LC 724 Find Pivot Index | P15: E | Q15: 15 | R15: ReviewQueue top 3 | S15: Draw a 3-way decision tree: When to use Two Pointers vs Sliding Window vs Hash Map | T15: Did you solve both problems within 30 minutes without looking at past code? | U15: Linear scan optimization is the foundation for GPU memory streaming | V15: Linear foundations mastery | AB15: —
A16: 15 | B16: 3 | C16: 46310 | D16: Binary search correctness from invariants, not from memory of a template | E16: Binary search (index) | F16: Half-open invariant; lower_bound vs upper_bound; off-by-one elimination | G16: YES | H16: =HYPERLINK("https://www.youtube.com/watch?v=DfljaUwZsOk", "Binary search boundaries: invariant-first approach") | I16: 25 | J16: Untimed | K16: Tutorial before | L16: LC 704 Binary Search | M16: E | N16: 10 | O16: LC 34 Find First and Last Position | P16: M | Q16: 25 | R16: LC 1004 Max Consecutive Ones III | S16: Write lower_bound AND upper_bound from memory with NO template; state the invariant of each | T16: Bug-free without a template? If no, that is F6 and it costs you in every future BS problem. | U16: Index lookups in sorted on-disk structures (SSTables, sorted file offsets) | V16: Boundary reasoning from invariants | AB16: =HYPERLINK("https://www.youtube.com/watch?v=DfljaUwZsOk", "▶ Watch (Padho with Pratyush) ↗")
A17: 16 | B17: 3 | C17: 46311 | D17: Binary search on broken monotonicity - rotated array | E17: Binary search (rotated) | F17: Detect the sorted half; prove the test is correct; handle duplicates | G17: NO | H17: - | J17: Untimed | K17: 1 hint @20min | L17: LC 33 Search in Rotated Sorted Array | M17: M | N17: 30 | O17: LC 153 Find Minimum in Rotated Sorted Array | P17: M | Q17: 20 | R17: LC 34 Find First and Last Position | S17: Explain which half is sorted, why the test is correct, and what breaks with duplicates (LC 81) | T17: Did you enumerate the 4 cases before coding, or debug into a solution? | U17: Circular buffers; ring-index math in lock-free queues | V17: Partial-order search | AB17: —
A18: 17 | B18: 3 | C18: 46312 | D18: Binary search ON THE ANSWER - the single highest-leverage pattern in this program | E18: Binary search on answer | F18: Monotone predicate feasible(x); search value space not index space | G18: YES | H18: =HYPERLINK("https://www.youtube.com/watch?v=C2apEw9pgtw", "Binary search on answer / parametric search") | I18: 25 | J18: Untimed | K18: Tutorial before, then solve alone with no help | L18: LC 875 Koko Eating Bananas | M18: M | N18: 25 | O18: LC 1011 Capacity to Ship Packages Within D Days | P18: M | Q18: 25 | R18: LC 33 Search in Rotated Sorted Array | S18: Write the 3 validity conditions for BS-on-answer: answer space bounded, predicate monotone, predicate fast | T18: Do 'minimize the maximum' and 'maximize the minimum' now trigger this pattern instantly? | U18: Capacity planning, autoscaling thresholds, batch-size selection, quota fitting, SLO optimization | V18: Parametric search | AB18: =HYPERLINK("https://www.youtube.com/watch?v=C2apEw9pgtw", "▶ Watch (Abdul Bari) ↗")
A19: 18 | B19: 3 | C19: 46313 | D19: [2-SOL] Harder predicate design - construct feasible() when it is not obvious | E19: Binary search on answer (hard predicates) | F19: feasible() construction; proving monotonicity | G19: NO | H19: - | J19: Untimed | K19: 1 hint @25min | L19: LC 410 Split Array Largest Sum | M19: H | N19: 40 | O19: LC 1482 Minimum Number of Days to Make m Bouquets | P19: M | Q19: 25 | R19: LC 875 Koko Eating Bananas | S19: Rederive feasible() for LC 410 with no notes; prove its monotonicity; find the DP alternative O(kn^2) | T19: Was your predicate actually monotone? Prove it - unproven predicates are guesses. | U19: Sharding load across workers under a max-per-worker bound; SLO-constrained batching | V19: Predicate construction + second solution (DP) | AB19: —
A20: 19 | B20: 3 | C20: 46314 | D20: Binary search where input is not a flat array; second solutions required | E20: Binary search (abstract) + partition | F20: count(<=x) counting search; binary search over a 2D structure | G20: NO | H20: - | J20: Untimed | K20: 1 hint @30min | L20: LC 378 Kth Smallest in a Sorted Matrix | M20: M | N20: 35 | O20: LC 4 Median of Two Sorted Arrays | P20: H | Q20: 45 | R20: LC 410 Split Array Largest Sum | S20: Explain BOTH: count(<=x) search and the O(log(min(m,n))) partition method for LC 4 | T20: Two genuinely different solutions found? If only one, you are template-locked. | U20: Quantile estimation over sorted shards; distributed k-th element queries | V20: Second-solution habit | AB20: —
A21: 20 | B21: 3 | C21: 46315 | D21: Blind mix: sort, window, or binary search - eliminate from constraints first | E21: Blind (W1-W3) | F21: Approach elimination from constraint reading; recognition speed | G21: NO | H21: - | J21: Timed-50 | K21: None | L21: LC 162 Find Peak Element | M21: M | N21: 20 | O21: LC 2300 Successful Pairs of Spells and Potions | P21: M | Q21: 25 | R21: LC 4 Median of Two Sorted Arrays | S21: For each: write the single constraint clue that revealed the pattern | T21: Time-to-pattern < 4 min for both? Record both numbers in MockInterviews. | U21: Threshold queries over sorted metric arrays in monitoring systems | V21: Fast elimination from constraint reading | AB21: —
A22: 21 | B22: 3 | C22: 46316 | D22: Week 3 - complexity drilling as a first-class skill (10 reps, no coding) | E22: Review/complexity | F22: Estimate TC/SC BEFORE coding; lower bounds; 10 targeted dreps | G22: NO | H22: - | J22: Untimed | K22: None | L22: 10 complexity drills: read problem -> brute TC -> target TC -> SC -> lower bound. No coding. | M22: - | N22: 30 | O22: Retest your 2 worst W3 problems | P22: M | Q22: 40 | R22: ReviewQueue top 3 | S22: Rederive the 3 BS-on-answer validity conditions; write 3 problems where it does NOT apply | T22: Complexity accuracy /10. Below 7 means F5 is your bottleneck, not algorithms. | U22: - | V22: Complexity fluency | AB22: —
A23: 22 | B23: 4 | C23: 46317 | D23: Sorting as preprocessing: what invariant does the sort create? | E23: Sort + linear scan | F23: Sort manufactures monotonicity you can exploit greedily; sort KEY matters | G23: NO | H23: - | J23: Untimed | K23: 1 hint @20min | L23: LC 56 Merge Intervals | M23: M | N23: 25 | O23: LC 435 Non-Overlapping Intervals | P23: M | Q23: 25 | R23: LC 2300 Successful Pairs of Spells and Potions | S23: State exactly what invariant the sort created in each problem, and why the sort key (start vs end) matters | T23: Did you justify the sort key, or try both until tests passed? | U23: Log compaction ordering; dedup windows; merging of sorted shard outputs in LSM-trees | V23: Preprocessing mindset | AB23: —
A24: 23 | B24: 4 | C24: 46318 | D24: Interval reasoning and sweep line - two equivalent views | E24: Intervals/sweep line | F24: Events +1/-1; heap-of-end-times as equivalent model | G24: YES | H24: =HYPERLINK("https://www.youtube.com/watch?v=Nq7ok-OyEpg", "Sweep line and event counting") | I24: 20 | J24: Untimed | K24: Tutorial before | L24: LC 253 Meeting Rooms II | M24: M | N24: 30 | O24: LC 1094 Car Pooling | P24: M | Q24: 20 | R24: LC 56 Merge Intervals | S24: Prove heap-of-ends and sweep-line give identical answers; state both complexities; derive the tie-breaking rule | T24: Two solutions for one problem - that is the target habit from today forward. | U24: Concurrent resource counting (GPU slots, DB connections); admission control | V24: Sweep-line modelling | AB24: =HYPERLINK("https://www.youtube.com/watch?v=Nq7ok-OyEpg", "▶ Watch (Striver) ↗")
A25: 24 | B25: 4 | C25: 46319 | D25: Monotonic stack from first principles - the amortized argument is everything | E25: Monotonic stack | F25: A pop resolves one answer; total pops <= n -> amortized O(n); stack holds invariant | G25: YES | H25: =HYPERLINK("https://www.youtube.com/watch?v=wiOo4DC5GGA", "Monotonic stack from first principles (amortized)") | I25: 25 | J25: Untimed | K25: Tutorial before | L25: LC 739 Daily Temperatures | M25: M | N25: 25 | O25: LC 503 Next Greater Element II (circular) | P25: M | Q25: 20 | R25: LC 253 Meeting Rooms II | S25: Explain the amortized bound out loud; state what the stack contains at any moment (the invariant) | T25: Could you explain the amortization to an interviewer in 60 seconds? Practise aloud. | U25: Detecting monotone breaks in metric streams (backpressure onset, latency spikes) | V25: Amortized analysis | AB25: =HYPERLINK("https://www.youtube.com/watch?v=wiOo4DC5GGA", "▶ Watch (Padho with Pratyush) ↗")
A26: 25 | B26: 4 | C26: 46320 | D26: Monotonic stack on spans and areas - boundary-span thinking | E26: Monotonic stack (boundaries) | F26: previous-smaller / next-smaller -> span formula; equal-element handling | G26: NO | H26: - | J26: Untimed | K26: 1 hint @30min | L26: LC 84 Largest Rectangle in Histogram | M26: H | N26: 40 | O26: LC 907 Sum of Subarray Minimums | P26: M | Q26: 35 | R26: LC 739 Daily Temperatures | S26: Derive width = right - left - 1 yourself; explain the equal-element double-counting fix for LC 907 | T26: Did you handle equal elements correctly BY DESIGN, or by trial and error? | U26: Peak-utilization rectangles over time-series capacity graphs; histogram-based alerting | V26: Boundary-span thinking | AB26: —
A27: 26 | B27: 4 | C27: 46321 | D27: [2-SOL] Monotonic deque + solve LC 42 Trapping Rain Water three ways | E27: Monotonic deque | F27: Deque holds only viable candidates in decreasing order; window max in O(n) | G27: NO | H27: - | J27: Untimed | K27: 1 hint @25min | L27: LC 239 Sliding Window Maximum | M27: H | N27: 30 | O27: LC 42 Trapping Rain Water (3 solutions) | P27: M | Q27: 30 | R27: LC 84 Largest Rectangle in Histogram | S27: Solve LC 42 three ways: prefix-max arrays, two pointers, monotonic stack. Compare TC/SC for each. | T27: How many of the three did you find WITHOUT help? That is your second-solution score. | U27: Rolling max latency over stream windows; watermarking in streaming pipelines | V27: Multi-solution flexibility | AB27: —
A28: 27 | B28: 4 | C28: 46322 | D28: Blind mix across weeks 1-4 - cross-pattern discrimination under time | E28: Blind (W1-W4 cross) | F28: Speed of pattern recognition; avoiding false pattern matches | G28: NO | H28: - | J28: Timed-55 | K28: None | L28: LC 621 Task Scheduler | M28: M | N28: 30 | O28: LC 452 Minimum Number of Arrows to Burst Balloons | P28: M | Q28: 20 | R28: LC 239 Sliding Window Maximum | S28: Write one-line recognition cues for ALL patterns from weeks 1-4 (~14 cues total) | T28: First-try correct pattern rate this week. Below 60% -> recognition, not knowledge, is the gap. | U28: Cooldown-constrained job scheduling = real scheduler behaviour in ML training systems | V28: Recognition speed | AB28: —
A29: 28 | B29: 4 | C29: 46323 | D29: MONTH 1 DIAGNOSTIC - 3 unlabelled, 90 min, zero hints, verbal explanation required | E29: Diagnostic | F29: Measure, do not learn. No pattern labels. No hints. | G29: NO | H29: - | J29: Diagnostic | K29: None | L29: LC 918 Max Sum Circular Subarray | M29: M | N29: 30 | O29: LC 795 Number of Subarrays with Bounded Max + LC 581 Shortest Unsorted Continuous Subarray (unlabelled) | P29: M | Q29: 60 | R29: - | S29: For each: log time-to-pattern, final TC/SC, correctness, hint-free, explanation quality | T29: Fill MockInterviews rows now. This is your baseline - do not soften any score. | U29: - | V29: Baseline measurement | AB29: —
A30: 29 | B30: 5 | C30: 46324 | D30: Heap mental model: partial order is enough; when to use heap vs sort | E30: Heap/top-K | F30: Why heap beats full sort when k<<n; heapify is O(n); min-heap vs max-heap | G30: YES | H30: =HYPERLINK("https://www.youtube.com/watch?v=NXOOYYwpbg4", "Heaps: sift-up/down, heapify, cost comparison") | I30: 25 | J30: Untimed | K30: Tutorial before | L30: LC 215 Kth Largest Element in Array | M30: M | N30: 25 | O30: LC 973 K Closest Points to Origin | P30: M | Q30: 20 | R30: LC 621 Task Scheduler | S30: State when sorting beats a heap and vice versa, with both complexities written out explicitly | T30: Can you compute and compare both costs, including constants? That is the skill. | U30: Top-K hot keys, request prioritisation, eviction candidate selection in caches | V30: Cost comparison reasoning | AB30: =HYPERLINK("https://www.youtube.com/watch?v=NXOOYYwpbg4", "▶ Watch (Aditya Verma) ↗")
A31: 30 | B31: 5 | C31: 46325 | D31: Two-heap invariants for streaming statistics | E31: Heap (streaming/online) | F31: Balanced max-heap/min-heap invariant; maintain the balance on every insert | G31: NO | H31: - | J31: Untimed | K31: 1 hint @25min | L31: LC 295 Find Median from Data Stream | M31: H | N31: 35 | O31: LC 1046 Last Stone Weight | P31: E | Q31: 15 | R31: LC 215 Kth Largest Element | S31: Write the two-heap invariant and rebalance rule BEFORE writing any code | T31: Did you define the invariant FIRST? That is the whole skill in streaming structure design. | U31: Online p50/p99 latency estimation without storing all samples; streaming quantiles | V31: Streaming state design | AB31: —
A32: 31 | B32: 5 | C32: 46326 | D32: Heap for k-way merging and greedy scheduling | E32: Heap (k-way merge) | F32: k-way merge; heap of active cursors; where the log k factor comes from | G32: NO | H32: - | J32: Untimed | K32: 1 hint @20min | L32: LC 23 Merge k Sorted Lists | M32: H | N32: 30 | O32: LC 767 Reorganize String | P32: M | Q32: 25 | R32: LC 295 Find Median from Data Stream | S32: Explain where log k comes from; give the divide-and-conquer merge alternative and its TC | T32: Correct TC derived, not guessed? Two algorithms compared? | U32: LSM-tree compaction; merging sorted shard outputs in distributed ML data pipelines | V32: Merge algorithms | AB32: —
A33: 32 | B33: 5 | C33: 46327 | D33: Greedy: the exchange argument - proof, not vibes | E33: Greedy invariants | F33: Exchange argument and staying-ahead argument; constructing counterexamples | G33: YES | H33: =HYPERLINK("https://www.youtube.com/watch?v=2Rr2tW9zvRg", "Proving greedy correctness: exchange and staying-ahead") | I33: 20 | J33: Untimed | K33: Tutorial before | L33: LC 45 Jump Game II | M33: M | N33: 30 | O33: LC 134 Gas Station | P33: M | Q33: 25 | R33: LC 23 Merge k Sorted Lists | S33: Write a full exchange-argument proof for LC 45; write the unique-start argument for LC 134 | T33: Did you PROVE it or trust it? Unproven greedy is the most common hard-interview failure. | U33: Chunked transfer decisions; admission control; retry budget allocation in ML serving | V33: Greedy proof technique | AB33: =HYPERLINK("https://www.youtube.com/watch?v=2Rr2tW9zvRg", "▶ Watch (Abdul Bari) ↗")
A34: 33 | B34: 5 | C34: 46328 | D34: Greedy vs DP - find where greedy breaks by constructing a counterexample | E34: Greedy vs DP | F34: Counterexample construction as a design discipline | G34: NO | H34: - | J34: Untimed | K34: 1 hint @30min | L34: LC 763 Partition Labels | M34: M | N34: 20 | O34: LC 871 Minimum Number of Refueling Stops | P34: H | Q34: 40 | R34: LC 45 Jump Game II | S34: Construct an input where a plausible greedy fails on LC 871; state why the heap-greedy is correct | T34: Can you break your own solution? If you cannot, you cannot trust it. | U34: Checkpoint placement in long ML training runs; spot-instance restart strategy | V34: Adversarial self-testing | AB34: —
A35: 34 | B35: 5 | C35: 46329 | D35: Blind mix: heap vs sort vs greedy vs simulation | E35: Blind (W5 mix) | F35: Cost-based structure selection under time pressure | G35: NO | H35: - | J35: Timed-60 | K35: None | L35: LC 2402 Meeting Rooms III | M35: H | N35: 40 | O35: LC 1834 Single-Threaded CPU | P35: M | Q35: 30 | R35: LC 871 Minimum Number of Refueling Stops | S35: Name the invariant each heap maintains in these problems and why two heaps are needed | T35: Simulation bugs count as F6, not F2 - the pattern is correct, the implementation failed. | U35: This IS a real scheduler: ready-queue + busy-resource queue with release events | V35: Simulation discipline | AB35: —
A36: 35 | B36: 5 | C36: 46330 | D36: Week 5 assessment: weakness-targeted retest | E36: Review/targeted repair | F36: Attack your dominant failure category directly | G36: NO | H36: - | J36: Untimed | K36: Hints allowed | L36: 3 problems from your most frequent failure category this week | M36: M | N36: 45 | O36: WeeklyAssessment + write preventive rules | P36: - | Q36: 20 | R36: ReviewQueue top 4 | S36: Rebuild two-heap median and k-way merge from a blank file | T36: Is your top failure category shrinking week over week? If not, the plan changes. | U36: - | V36: Targeted repair | AB36: —
A37: 36 | B37: 6 | C37: 46331 | D37: Pointer surgery: linked-list invariants - reason before running, no debugger | E37: Linked list pointers | F37: Dummy head; prev/curr discipline; draw state transitions before coding | G37: NO | H37: - | J37: Untimed | K37: 1 hint @20min | L37: LC 206 Reverse Linked List | M37: E | N37: 12 | O37: LC 143 Reorder List | P37: M | Q37: 25 | R37: LC 1834 Single-Threaded CPU | S37: Draw pointer states before/after EACH statement for LC 143 - no debugger allowed | T37: Did you reason through it, or print-debug your way into a solution? | U37: Free lists and intrusive linked lists in memory allocators | V37: Precise state mutation | AB37: —
A38: 37 | B38: 6 | C38: 46332 | D38: [2-SOL] O(1) cache design: compose hashmap + doubly linked list | E38: Design (LRU) | F38: Composing two structures for O(1) on all ops; API drives structure choice | G38: YES | H38: =HYPERLINK("https://www.youtube.com/watch?v=R_Mfw4ew-Vo", "LRU cache design: structure composition from requirements") | I38: 20 | J38: Untimed | K38: Tutorial before | L38: LC 146 LRU Cache | M38: M | N38: 35 | O38: LC 142 Linked List Cycle II | P38: M | Q38: 25 | R38: LC 143 Reorder List | S38: Rebuild LRU from an empty file with no notes; then explain Floyd's cycle detection proof | T38: Can you write a clean LRU in under 20 minutes? This is a baseline infra expectation. | U38: Page cache eviction; KV-store eviction; embedding/feature cache in ML serving | V38: Structure composition from API requirements | AB38: =HYPERLINK("https://www.youtube.com/watch?v=R_Mfw4ew-Vo", "▶ Watch (Striver) ↗")
A39: 38 | B39: 6 | C39: 46333 | D39: Frequency-aware eviction: LFU - minFreq pointer invariant | E39: Design (LFU) | F39: Bucketing by frequency; minFreq can only increase by 1 on access | G39: NO | H39: - | J39: Untimed | K39: 1 hint @30min | L39: LC 460 LFU Cache | M39: H | N39: 45 | O39: LC 362 Design Hit Counter | P39: M | Q39: 20 | R39: LC 146 LRU Cache | S39: Explain the minFreq invariant and why it increases by at most 1 on any access | T39: For an ML feature cache: LRU or LFU? Defend with an access-pattern argument. | U39: Feature-store caching; embedding cache eviction; hot-shard detection in key-value systems | V39: Advanced structure design | AB39: —
A40: 39 | B40: 6 | C40: 46334 | D40: Bit manipulation as set/state encoding | E40: Bit manipulation | F40: Masks as tiny sets; XOR invariants; popcount; iterate subsets | G40: YES | H40: =HYPERLINK("https://www.youtube.com/watch?v=xXKL9YBWgCY", "Bit tricks that actually recur in interviews") | I40: 20 | J40: Untimed | K40: Tutorial before | L40: LC 137 Single Number II | M40: M | N40: 25 | O40: LC 371 Sum of Two Integers | P40: M | Q40: 20 | R40: LC 460 LFU Cache | S40: Explain XOR/counting-bits invariant; write mask ops for add/remove/test/iterate-all-subsets | T40: Do you now see bitmask=tiny-set automatically? You will need this in week 13. | U40: Bitmaps; feature flags; GPU lane masks; bloom-filter bit operations | V40: State compression | AB40: =HYPERLINK("https://www.youtube.com/watch?v=xXKL9YBWgCY", "▶ Watch (Errichto) ↗")
...

Sheet PatternLibrary
A1: Pattern | B1: Recognition Cues | C1: Typical Constraints | D1: Core Idea | E1: Key Data Structures | F1: Common Traps | G1: Complexity Target | H1: Example Problem Types | I1: AI-Infra Relevance | J1: Mastery (1-5) | K1: # times it appeared in plan | L1: Last practiced
A2: Complexity calibration | B2: Any problem with 'efficient' + a large n stated | C2: n in constraints | D2: Derive acceptable TC from n BEFORE designing anything; eliminate approaches that cannot fit | E2: None - pure reasoning | F2: Assuming O(n^2) passes at n=10^5; ignoring hash/recursion constants; never doing this step | G2: Pre-code decision | H2: Every single problem | I2: Latency budgets; SLO thresholds; batch-size selection | K2: =COUNTIF(DayPlan!$E$2:$E$169,"*Complexity*") | L2: =IF(MAXIFS(ProblemDB!$F$2:$F$750,ProblemDB!$D$2:$D$750,"*Complexity*")>0,MAXIFS(ProblemDB!$F$2:$F$750,ProblemDB!$D$2:$D$750,"*Complexity*"),"-")
A3: Frequency/counting + hashing | B3: 'anagram','k most frequent','duplicates','count of','appears more than once' | C3: values bounded or hashable; n up to 10^6 | D3: Replace repeated scans with one pass building counts; hash the KEY that captures the invariant | E3: hash map, count array, bucket array | F3: Counting when positions matter; wrong key granularity; using set when count needed | G3: O(n) time, O(k) space | H3: Group anagrams, top-K, majority element, first unique character | I3: Hot-key detection, metric counters, histogram-based alerting | K3: =COUNTIF(DayPlan!$E$2:$E$169,"*Frequency*") | L3: =IF(MAXIFS(ProblemDB!$F$2:$F$750,ProblemDB!$D$2:$D$750,"*Frequency*")>0,MAXIFS(ProblemDB!$F$2:$F$750,ProblemDB!$D$2:$D$750,"*Frequency*"),"-")
A4: Prefix/suffix reasoning | B4: 'subarray sum','range query','product except self','subarrays satisfying condition' | C4: static array, multiple queries, O(n) target | D4: Precompute cumulative info so any range is O(1); prefix+hash converts a condition into a lookup | E4: prefix array, hash map (prefix -> count or prefix -> first-index) | F4: Forgetting prefix[0]=0; using seen-set instead of count-map; applying to non-additive functions | G4: O(n) build, O(1) query | H4: Range sums, balanced subarrays, product except self, 2D regions | I4: Rolling aggregates, cumulative metrics, event-log windows | K4: =COUNTIF(DayPlan!$E$2:$E$169,"*Prefix*") | L4: =IF(MAXIFS(ProblemDB!$F$2:$F$750,ProblemDB!$D$2:$D$750,"*Prefix*")>0,MAXIFS(ProblemDB!$F$2:$F$750,ProblemDB!$D$2:$D$750,"*Prefix*"),"-")
A5: Two pointers (opposite ends) | B5: sorted or sortable input; 'pair/triplet sums to'; 'maximum area between' | C5: sorted or O(n log n) sort acceptable | D5: Move the pointer that provably cannot improve the answer; prove no valid pair is skipped | E5: two indices into the same array | F5: Moving the wrong pointer; skipping duplicates incorrectly; not proving the discard | G5: O(n) after sort | H5: Two Sum II, 3Sum, Container With Most Water | I5: Merging sorted shard scans; two-way join on sorted data | K5: =COUNTIF(DayPlan!$E$2:$E$169,"*opposite ends*") | L5: =IF(MAXIFS(ProblemDB!$F$2:$F$750,ProblemDB!$D$2:$D$750,"*opposite ends*")>0,MAXIFS(ProblemDB!$F$2:$F$750,ProblemDB!$D$2:$D$750,"*opposite ends*"),"-")
A6: Two pointers (same direction / read-write) | B6: 'in place','remove elements','partition','k-th from end' | C6: O(1) extra space required; array mutation allowed | D6: Separate a slow write-index from a fast read-index; maintain a region invariant | E6: two indices, optional dummy node for lists | F6: Overwriting needed elements; not stating the region invariant; off-by-one | G6: O(n) time, O(1) space | H6: Remove duplicates, Sort Colors, move zeros, linked-list operations | I6: In-place buffer compaction; zero-copy stream rewriting | K6: =COUNTIF(DayPlan!$E$2:$E$169,"*read/write*") | L6: =IF(MAXIFS(ProblemDB!$F$2:$F$750,ProblemDB!$D$2:$D$750,"*read/write*")>0,MAXIFS(ProblemDB!$F$2:$F$750,ProblemDB!$D$2:$D$750,"*read/write*"),"-")
A7: Sliding window (variable) | B7: 'longest/shortest subarray/substring satisfying condition'; contiguous required | C7: monotone feasibility must hold; n up to 10^5 | D7: Grow right pointer; shrink left while invalid. ONLY valid when extending cannot repair a violation. | E7: hash map or count array for window contents, two indices | F7: Applying to non-monotone conditions (e.g. sum>=k with negatives); wrong shrink condition | G7: O(n) | H7: Longest unique substring, minimum size subarray sum, fruit into baskets | I7: Rate limiting, windowed quotas, token bucket | K7: =COUNTIF(DayPlan!$E$2:$E$169,"*variable*") | L7: =IF(MAXIFS(ProblemDB!$F$2:$F$750,ProblemDB!$D$2:$D$750,"*variable*")>0,MAXIFS(ProblemDB!$F$2:$F$750,ProblemDB!$D$2:$D$750,"*variable*"),"-")
A8: Sliding window + counting | B8: 'at most K distinct','replace at most k characters','subarrays with exactly k' | C8: alphabet/cardinality bounded; n up to 10^5 | D8: Track frequency inside the window; exactly(K) = atMost(K) - atMost(K-1) | E8: hash map, freq array, maxFreq variable | F8: Recomputing maxFreq on every shrink; wrong atMost monotonicity assumption | G8: O(n) or O(n | |alphabet|) | H8: Longest repeating character replacement, K different integers, permutation in string | I8: Cardinality-bounded caches; distinct-key windows in streaming analytics | K8: =COUNTIF(DayPlan!$E$2:$E$169,"*frequency*") | L8: =IF(MAXIFS(ProblemDB!$F$2:$F$750,ProblemDB!$D$2:$D$750,"*frequency*")>0,MAXIFS(ProblemDB!$F$2:$F$750,ProblemDB!$D$2:$D$750,"*frequency*"),"-")
A9: Binary search (index) | B9: sorted array; 'first/last position'; 'O(log n) required' | C9: sorted, or search space has a monotone property; n up to 10^7 | D9: Maintain a half-open invariant (lo<=answer<hi); shrink systematically; no templates | E9: sorted array (or implicit sorted space) | F9: Off-by-one errors; lo<hi vs lo<=hi confusion; infinite loops; wrong mid formula | G9: O(log n) | H9: Binary search, first/last position, find minimum in rotated array | I9: SSTable lookups, sorted offset indexes, version search | K9: =COUNTIF(DayPlan!$E$2:$E$169,"*Binary search*") | L9: =IF(MAXIFS(ProblemDB!$F$2:$F$750,ProblemDB!$D$2:$D$750,"*Binary search*")>0,MAXIFS(ProblemDB!$F$2:$F$750,ProblemDB!$D$2:$D$750,"*Binary search*"),"-")
A10: Binary search on answer | B10: 'minimize the maximum','maximize the minimum','minimum capacity/speed/time'; large answer range | C10: answer <= 10^9, predicate check is O(n) or O(n log n) | D10: Search the ANSWER SPACE with a monotone feasible(x) predicate; 3 validity conditions must hold | E10: feasibility predicate function + binary search loop | F10: Non-monotone predicate; wrong search bounds; predicate accidentally O(n^2) | G10: O(n log(answer_range)) | H10: Koko eating bananas, ship packages, split array, min days for bouquets | I10: Capacity planning, autoscaling, SLO fitting, quota allocation | K10: =COUNTIF(DayPlan!$E$2:$E$169,"*Binary search on answer*") | L10: =IF(MAXIFS(ProblemDB!$F$2:$F$750,ProblemDB!$D$2:$D$750,"*Binary search on answer*")>0,MAXIFS(ProblemDB!$F$2:$F$750,ProblemDB!$D$2:$D$750,"*Binary search on answer*"),"-")
A11: Sort + linear scan (preprocessing) | B11: 'intervals','pairs','sorted input assumed'; O(n log n) acceptable | C11: n up to 10^5, no online queries | D11: Sorting creates a monotonicity you can then exploit with a single greedy pass | E11: sort + one or two pointers or a heap | F11: Wrong sort key (start vs end vs value); assuming stability; sorting when a heap suffices | G11: O(n log n) | H11: Merge intervals, non-overlapping intervals, sort colors, meeting rooms | I11: Log compaction ordering, sorted shard merging, LSM-tree compaction | K11: =COUNTIF(DayPlan!$E$2:$E$169,"*Sort*") | L11: =IF(MAXIFS(ProblemDB!$F$2:$F$750,ProblemDB!$D$2:$D$750,"*Sort*")>0,MAXIFS(ProblemDB!$F$2:$F$750,ProblemDB!$D$2:$D$750,"*Sort*"),"-")
A12: Interval / sweep line | B12: 'overlapping intervals','maximum concurrent events','resources needed at peak' | C12: intervals, events with timestamps; n up to 10^5 | D12: Convert intervals to +1/-1 events and sweep; or maintain a min-heap of active end times | E12: sorted events array, min-heap of end times | F12: Tie-breaking between end and start at the same time; off-by-one on closed intervals | G12: O(n log n) | H12: Meeting rooms II, car pooling, calendar, task scheduler | I12: Concurrent resource counting (GPU/CPU slots), admission control | K12: =COUNTIF(DayPlan!$E$2:$E$169,"*Interval*") | L12: =IF(MAXIFS(ProblemDB!$F$2:$F$750,ProblemDB!$D$2:$D$750,"*Interval*")>0,MAXIFS(ProblemDB!$F$2:$F$750,ProblemDB!$D$2:$D$750,"*Interval*"),"-")
A13: Monotonic stack | B13: 'next greater/smaller element','previous smaller','span','largest rectangle' | C13: array; n up to 10^5 | D13: Keep a monotone stack; each pop resolves one answer; total pops <= n -> amortized O(n) | E13: stack of indices (not values) | F13: Storing values not indices; equal-element double counting; missing sentinel flush at end | G13: O(n) amortized | H13: Daily temperatures, next greater element, largest rectangle in histogram, subarray minimums | I13: Monotone-break detection in metric streams, backpressure onset | K13: =COUNTIF(DayPlan!$E$2:$E$169,"*Monotonic stack*") | L13: =IF(MAXIFS(ProblemDB!$F$2:$F$750,ProblemDB!$D$2:$D$750,"*Monotonic stack*")>0,MAXIFS(ProblemDB!$F$2:$F$750,ProblemDB!$D$2:$D$750,"*Monotonic stack*"),"-")
A14: Monotonic deque | B14: 'maximum/minimum of every window of size k','sliding extremum','windowed DP' | C14: fixed or bounded window; n up to 10^6 | D14: Maintain a deque of indices in monotone order; evict out-of-window and dominated candidates | E14: deque of indices | F14: Not evicting expired indices; storing values not indices; wrong eviction order | G14: O(n) | H14: Sliding window maximum, jump game VI, constrained subsequence sum | I14: Rolling max latency, watermarks, windowed DP in schedulers | K14: =COUNTIF(DayPlan!$E$2:$E$169,"*Monotonic deque*") | L14: =IF(MAXIFS(ProblemDB!$F$2:$F$750,ProblemDB!$D$2:$D$750,"*Monotonic deque*")>0,MAXIFS(ProblemDB!$F$2:$F$750,ProblemDB!$D$2:$D$750,"*Monotonic deque*"),"-")
A15: Heap / top-K / streaming extremum | B15: 'k largest/smallest','median of stream','schedule next available resource' | C15: k<<n or online data; n up to 10^6 | D15: Partial order is enough; a heap gives the extreme in O(log n); heapify is O(n) | E15: min-heap or max-heap; two heaps for median; heap of (key, cursor) for merge | F15: Full sort when k is tiny; wrong polarity; not using lazy deletion for stale entries | G15: O(n log k) or O(log n) per operation | H15: Kth largest, k closest, find median from stream, merge k sorted lists, task scheduler | I15: Top-K hot keys, p99 estimation, eviction candidate selection, priority scheduling | K15: =COUNTIF(DayPlan!$E$2:$E$169,"*Heap*") | L15: =IF(MAXIFS(ProblemDB!$F$2:$F$750,ProblemDB!$D$2:$D$750,"*Heap*")>0,MAXIFS(ProblemDB!$F$2:$F$750,ProblemDB!$D$2:$D$750,"*Heap*"),"-")
A16: Greedy invariants | B16: 'maximum number of','minimum steps','locally safe choice'; often after sorting | C16: exchange argument must hold; usually O(n log n) | D16: Prove by exchange or staying-ahead that the local choice is in some optimal solution | E16: sort + counters, heap, or simple scan | F16: Unproven greedy; missing a counterexample that breaks it; using greedy where DP is required | G16: O(n log n) typically | H16: Jump game II, gas station, partition labels, refueling stops | I16: Admission control, retry budgets, checkpoint placement | K16: =COUNTIF(DayPlan!$E$2:$E$169,"*Greedy*") | L16: =IF(MAXIFS(ProblemDB!$F$2:$F$750,ProblemDB!$D$2:$D$750,"*Greedy*")>0,MAXIFS(ProblemDB!$F$2:$F$750,ProblemDB!$D$2:$D$750,"*Greedy*"),"-")
A17: Design / structure composition | B17: 'implement X with O(1) get/put/delete','LRU','LFU','getRandom' | C17: operation TC is the spec; n up to 10^5 ops | D17: Compose two structures so each required operation is O(1)/O(log n); API dictates structures | E17: hash map + doubly linked list (LRU), freq buckets + maps (LFU), array + index map (getRandom) | F17: Choosing structures by habit not by API; forgetting to keep both structures in sync on every path | G17: O(1) per operation | H17: LRU cache, LFU cache, RandomizedSet, TimeMap, hit counter | I17: Page/feature/embedding caches, KV stores, rate limiters, versioned stores | K17: =COUNTIF(DayPlan!$E$2:$E$169,"*Design*") | L17: =IF(MAXIFS(ProblemDB!$F$2:$F$750,ProblemDB!$D$2:$D$750,"*Design*")>0,MAXIFS(ProblemDB!$F$2:$F$750,ProblemDB!$D$2:$D$750,"*Design*"),"-")
A18: Bit manipulation | B18: 'subset of at most 20 items','XOR','without extra space','count bits','feature flags' | C18: n<=20 for subset enumeration; 32/64-bit word for bit tricks | D18: A bitmask is a tiny set with O(1) set operations; XOR cancels pairs; use popcount for size | E18: integer masks, popcount, __builtin_ctz | F18: Signed right-shifts; operator precedence bugs (use parentheses); overflow on mask<<1 | G18: O(1) per mask op; O(2^n) for full enumeration | H18: Single number II, sum without +, missing number, subset enumeration | I18: Bitmaps, feature flags, GPU lane/warp masks, bloom filter ops | K18: =COUNTIF(DayPlan!$E$2:$E$169,"*Bit*") | L18: =IF(MAXIFS(ProblemDB!$F$2:$F$750,ProblemDB!$D$2:$D$750,"*Bit*")>0,MAXIFS(ProblemDB!$F$2:$F$750,ProblemDB!$D$2:$D$750,"*Bit*"),"-")
A19: Tree recursion (contract-first) | B19: 'depth','balanced','path sum','subtree property','lowest common ancestor' | C19: n up to 10^5; beware recursion depth on skewed trees | D19: Define exactly what the function returns for a subtree; write it in English before coding; then trust it | E19: recursion, call stack, optional memoisation | F19: Vague contracts; mixing 'answer' with 'return value'; stack overflow on skewed trees | G19: O(n) | H19: Depth, balanced, diameter, max path sum, LCA, validate BST | I19: Recursive dependency evaluation, nested config resolution | K19: =COUNTIF(DayPlan!$E$2:$E$169,"*Tree recursion*") | L19: =IF(MAXIFS(ProblemDB!$F$2:$F$750,ProblemDB!$D$2:$D$750,"*Tree recursion*")>0,MAXIFS(ProblemDB!$F$2:$F$750,ProblemDB!$D$2:$D$750,"*Tree recursion*"),"-")
A20: Tree DP (post-order) | B20: 'max path','rob houses in tree','distribute coins','max sum with no adjacent' | C20: tree, single-pass wanted | D20: Combine children's return values at the parent; return one value upward; update global answer separately | E20: recursion + tuple return (gain upward, answer updated) | F20: Returning the global answer upward; double-counting the root node; forgetting to clamp negatives | G20: O(n) | H20: Diameter, max path sum, house robber III, distribute coins | I20: Aggregating metrics up a topology/ownership tree | K20: =COUNTIF(DayPlan!$E$2:$E$169,"*Tree DP*") | L20: =IF(MAXIFS(ProblemDB!$F$2:$F$750,ProblemDB!$D$2:$D$750,"*Tree DP*")>0,MAXIFS(ProblemDB!$F$2:$F$750,ProblemDB!$D$2:$D$750,"*Tree DP*"),"-")
A21: BST ordering | B21: 'validate BST','k-th smallest in BST','BST range queries' | C21: BST given, may be unbalanced | D21: In-order traversal is sorted; propagate valid range (lo, hi) top-down instead of comparing parent-child | E21: recursion with range bounds, iterative inorder stack | F21: Comparing only parent-child (misses deep violations); ignoring duplicate policy | G21: O(h) per operation | H21: Validate BST, kth smallest, insert/delete, range queries | I21: Ordered indexes, range scans, B-tree node invariants | K21: =COUNTIF(DayPlan!$E$2:$E$169,"*BST*") | L21: =IF(MAXIFS(ProblemDB!$F$2:$F$750,ProblemDB!$D$2:$D$750,"*BST*")>0,MAXIFS(ProblemDB!$F$2:$F$750,ProblemDB!$D$2:$D$750,"*BST*"),"-")
A22: BFS levels / shortest hops | B22: 'minimum steps','level order','nearest X','spread from source' | C22: unweighted graph or grid; n up to 10^5 | D22: First visit = shortest distance; seed all sources at level 0 for multi-source; expand in layers | E22: queue, visited set/array | F22: Marking visited on pop (causes exponential blowup); mixing level boundaries | G22: O(V+E) | H22: Rotting oranges, word ladder, open the lock, right side view, 01-matrix | I22: Hop counts, blast-radius analysis, BFS-based propagation | K22: =COUNTIF(DayPlan!$E$2:$E$169,"*BFS*") | L22: =IF(MAXIFS(ProblemDB!$F$2:$F$750,ProblemDB!$D$2:$D$750,"*BFS*")>0,MAXIFS(ProblemDB!$F$2:$F$750,ProblemDB!$D$2:$D$750,"*BFS*"),"-")
A23: Graph DFS / components | B23: 'islands','connected components','clone graph','cycle detection','safe states' | C23: grid or adjacency list; n up to 10^5 | D23: Explore exhaustively; component identity or cycle colour (white/grey/black) is the output | E23: recursion or explicit stack, visited array, colour array for directed cycles | F23: Recursion depth on large grids; not handling multiple components; directed vs undirected cycle logic | G23: O(V+E) | H23: Number of islands, clone graph, find eventual safe states, course schedule | I23: Topology discovery, cluster membership, service-graph crawling | K23: =COUNTIF(DayPlan!$E$2:$E$169,"*Graph*") | L23: =IF(MAXIFS(ProblemDB!$F$2:$F$750,ProblemDB!$D$2:$D$750,"*Graph*")>0,MAXIFS(ProblemDB!$F$2:$F$750,ProblemDB!$D$2:$D$750,"*Graph*"),"-")
